Workbook
Name Fecha__2025_01_01_WinCalendar: 'CA Gráfico 2025'!$E$5
Name Fecha__2025_01_02_WinCalendar: 'CA Gráfico 2025'!$F$5
Name Fecha__2025_01_03_WinCalendar: 'CA Gráfico 2025'!$G$5
Name Fecha__2025_01_04_WinCalendar: 'CA Gráfico 2025'!$H$5
Name Fecha__2025_01_05_WinCalendar: 'CA Gráfico 2025'!$I$5
Name Fecha__2025_01_06_WinCalendar: 'CA Gráfico 2025'!$C$6
Name Fecha__2025_01_07_WinCalendar: 'CA Gráfico 2025'!$D$6
Name Fecha__2025_01_08_WinCalendar: 'CA Gráfico 2025'!$E$6
Name Fecha__2025_01_09_WinCalendar: 'CA Gráfico 2025'!$F$6
Name Fecha__2025_01_10_WinCalendar: 'CA Gráfico 2025'!$G$6
Name Fecha__2025_01_11_WinCalendar: 'CA Gráfico 2025'!$H$6
Name Fecha__2025_01_12_WinCalendar: 'CA Gráfico 2025'!$I$6
Name Fecha__2025_01_13_WinCalendar: 'CA Gráfico 2025'!$C$7
Name Fecha__2025_01_14_WinCalendar: 'CA Gráfico 2025'!$D$7
Name Fecha__2025_01_15_WinCalendar: 'CA Gráfico 2025'!$E$7
Name Fecha__2025_01_16_WinCalendar: 'CA Gráfico 2025'!$F$7
Name Fecha__2025_01_17_WinCalendar: 'CA Gráfico 2025'!$G$7
Name Fecha__2025_01_18_WinCalendar: 'CA Gráfico 2025'!$H$7
Name Fecha__2025_01_19_WinCalendar: 'CA Gráfico 2025'!$I$7
Name Fecha__2025_01_20_WinCalendar: 'CA Gráfico 2025'!$C$8
Name Fecha__2025_01_21_WinCalendar: 'CA Gráfico 2025'!$D$8
Name Fecha__2025_01_22_WinCalendar: 'CA Gráfico 2025'!$E$8
Name Fecha__2025_01_23_WinCalendar: 'CA Gráfico 2025'!$F$8
Name Fecha__2025_01_24_WinCalendar: 'CA Gráfico 2025'!$G$8
Name Fecha__2025_01_25_WinCalendar: 'CA Gráfico 2025'!$H$8
Name Fecha__2025_01_26_WinCalendar: 'CA Gráfico 2025'!$I$8
Name Fecha__2025_01_27_WinCalendar: 'CA Gráfico 2025'!$C$9
Name Fecha__2025_01_28_WinCalendar: 'CA Gráfico 2025'!$D$9
Name Fecha__2025_01_29_WinCalendar: 'CA Gráfico 2025'!$E$9
Name Fecha__2025_01_30_WinCalendar: 'CA Gráfico 2025'!$F$9
Name Fecha__2025_01_31_WinCalendar: 'CA Gráfico 2025'!$G$9
Name Fecha__2025_02_01_WinCalendar: 'CA Gráfico 2025'!$Q$5
Name Fecha__2025_02_02_WinCalendar: 'CA Gráfico 2025'!$R$5
Name Fecha__2025_02_03_WinCalendar: 'CA Gráfico 2025'!$L$6
Name Fecha__2025_02_04_WinCalendar: 'CA Gráfico 2025'!$M$6
Name Fecha__2025_02_05_WinCalendar: 'CA Gráfico 2025'!$N$6
Name Fecha__2025_02_06_WinCalendar: 'CA Gráfico 2025'!$O$6
Name Fecha__2025_02_07_WinCalendar: 'CA Gráfico 2025'!$P$6
Name Fecha__2025_02_08_WinCalendar: 'CA Gráfico 2025'!$Q$6
Name Fecha__2025_02_09_WinCalendar: 'CA Gráfico 2025'!$R$6
Name Fecha__2025_02_10_WinCalendar: 'CA Gráfico 2025'!$L$7
Name Fecha__2025_02_11_WinCalendar: 'CA Gráfico 2025'!$M$7
Name Fecha__2025_02_12_WinCalendar: 'CA Gráfico 2025'!$N$7
Name Fecha__2025_02_13_WinCalendar: 'CA Gráfico 2025'!$O$7
Name Fecha__2025_02_14_WinCalendar: 'CA Gráfico 2025'!$P$7
Name Fecha__2025_02_15_WinCalendar: 'CA Gráfico 2025'!$Q$7
Name Fecha__2025_02_16_WinCalendar: 'CA Gráfico 2025'!$R$7
Name Fecha__2025_02_17_WinCalendar: 'CA Gráfico 2025'!$L$8
Name Fecha__2025_02_18_WinCalendar: 'CA Gráfico 2025'!$M$8
Name Fecha__2025_02_19_WinCalendar: 'CA Gráfico 2025'!$N$8
Name Fecha__2025_02_20_WinCalendar: 'CA Gráfico 2025'!$O$8
Name Fecha__2025_02_21_WinCalendar: 'CA Gráfico 2025'!$P$8
Name Fecha__2025_02_22_WinCalendar: 'CA Gráfico 2025'!$Q$8
Name Fecha__2025_02_23_WinCalendar: 'CA Gráfico 2025'!$R$8
Name Fecha__2025_02_24_WinCalendar: 'CA Gráfico 2025'!$L$9
Name Fecha__2025_02_25_WinCalendar: 'CA Gráfico 2025'!$M$9
Name Fecha__2025_02_26_WinCalendar: 'CA Gráfico 2025'!$N$9
Name Fecha__2025_02_27_WinCalendar: 'CA Gráfico 2025'!$O$9
Name Fecha__2025_02_28_WinCalendar: 'CA Gráfico 2025'!$P$9
Name Fecha__2025_03_01_WinCalendar: 'CA Gráfico 2025'!$Z$5

Sheet CA Gráfico 2025
B1: INSTITUTO PROFESIONAL DUOC UC CALENDARIO ACADÉMICO 2025
B3: Semana | E3: Enero 2025 | K3: Semana | N3: Febrero 2025 | T3: Semana | W3: Marzo 2025 | AC3: Semana | AF3: Abril 2025
C4: Lun. | D4: Mar. | E4: Mié. | F4: Jue. | G4: Vie. | H4: Sáb. | I4: Dom. | L4: Lun. | M4: Mar. | N4: Mié. | O4: Jue. | P4: Vie. | Q4: Sáb. | R4: Dom. | U4: Lun. | V4: Mar. | W4: Mié. | X4: Jue. | Y4: Vie. | Z4: Sáb. | AA4: Dom. | AD4: Lun. | AE4: Mar. | AF4: Mié. | AG4: Jue. | AH4: Vie. | AI4: Sáb. | AJ4: Dom.
F5: 46023 | G5: 46024 | H5: 46025 | I5: 46026 | K5: 4 | Q5: 45689 | R5: 45690 | Z5: 45717 | AA5: 45718 | AC5: 4 | AE5: 45748 | AF5: 45749 | AG5: 45750 | AH5: 45751 | AI5: 45752 | AJ5: 45753
B6: 1 | C6: 45663 | D6: 45664 | E6: 45665 | F6: 45666 | G6: 45667 | H6: 45668 | I6: 45669 | K6: 5 | L6: 45691 | M6: 45692 | N6: 45693 | O6: 45694 | P6: 45695 | Q6: 45696 | R6: 45697 | U6: 45719 | V6: 45720 | W6: 45721 | X6: 45722 | Y6: 45723 | Z6: 45724 | AA6: 45725 | AC6: 5 | AD6: 45754 | AE6: 45755 | AF6: 45756 | AG6: 45757 | AH6: 45758 | AI6: 45759 | AJ6: 45760
B7: 2 | C7: 45670 | D7: 45671 | E7: 45672 | F7: 45673 | G7: 45674 | H7: 45675 | I7: 45676 | K7: 6 | L7: 45698 | M7: 45699 | N7: 45700 | O7: 45701 | P7: 45702 | Q7: 45703 | R7: 45704 | T7: 1 | U7: 45726 | V7: 45727 | W7: 45728 | X7: 45729 | Y7: 45730 | Z7: 45731 | AA7: 45732 | AC7: 6 | AD7: 45761 | AE7: 45762 | AF7: 45763 | AG7: 45764 | AH7: 45765 | AI7: 45766 | AJ7: 45767
B8: 3 | C8: 45677 | D8: 45678 | E8: 45679 | F8: 45680 | G8: 45681 | H8: 45682 | I8: 45683 | L8: 45705 | M8: 45706 | N8: 45707 | O8: 45708 | P8: 45709 | Q8: 45710 | R8: 45711 | T8: 2 | U8: 45733 | V8: 45734 | W8: 45735 | X8: 45736 | Y8: 45737 | Z8: 45738 | AA8: 45739 | AC8: 7 | AD8: 45768 | AE8: 45769 | AF8: 45770 | AG8: 45771 | AH8: 45772 | AI8: 45773 | AJ8: 45774
B9: 4 | C9: 45684 | D9: 45685 | E9: 45686 | F9: 45687 | G9: 45688 | L9: 45712 | M9: 45713 | N9: 45714 | O9: 45715 | P9: 45716 | T9: 3 | U9: 45740 | V9: 45741 | W9: 45742 | X9: 45743 | Y9: 45744 | Z9: 45745 | AA9: 45746 | AC9: 8 | AD9: 45775 | AE9: 45776 | AF9: 45777
T10: 4 | U10: 45747
B12: Semana | E12: Mayo 2025 | K12: Semana | N12: Junio 2025 | T12: Semana | W12: Julio 2025 | AC12: Semana | AF12: Agosto 2025
C13: Lun. | D13: Mar. | E13: Mié. | F13: Jue. | G13: Vie. | H13: Sáb. | I13: Dom. | L13: Lun. | M13: Mar. | N13: Mié. | O13: Jue. | P13: Vie. | Q13: Sáb. | R13: Dom. | U13: Lun. | V13: Mar. | W13: Mié. | X13: Jue. | Y13: Vie. | Z13: Sáb. | AA13: Dom. | AD13: Lun. | AE13: Mar. | AF13: Mié. | AG13: Jue. | AH13: Vie. | AI13: Sáb. | AJ13: Dom.
B14: 8 | F14: 45778 | G14: 45779 | H14: 45780 | I14: 45781 | K14: 12 | R14: 45809 | T14: 17 | V14: 45839 | W14: 45840 | X14: 45841 | Y14: 45842 | Z14: 45843 | AA14: 45844 | AH14: 45870 | AI14: 45871 | AJ14: 45872
B15: 9 | C15: 45782 | D15: 45783 | E15: 45784 | F15: 45785 | G15: 45786 | H15: 45787 | I15: 45788 | K15: 13 | L15: 45810 | M15: 45811 | N15: 45812 | O15: 45813 | P15: 45814 | Q15: 45815 | R15: 45816 | T15: 18 | U15: 45845 | V15: 45846 | W15: 45847 | X15: 45848 | Y15: 45849 | Z15: 45850 | AA15: 45851 | AD15: 45873 | AE15: 45874 | AF15: 45875 | AG15: 45876 | AH15: 45877 | AI15: 45878 | AJ15: 45879
B16: 10 | C16: 45789 | D16: 45790 | E16: 45791 | F16: 45792 | G16: 45793 | H16: 45794 | I16: 45795 | K16: 14 | L16: 45817 | M16: 45818 | N16: 45819 | O16: 45820 | P16: 45821 | Q16: 45822 | R16: 45823 | T16: 19 | U16: 45852 | V16: 45853 | W16: 45854 | X16: 45855 | Y16: 45856 | Z16: 45857 | AA16: 45858 | AC16: 1 | AD16: 45880 | AE16: 45881 | AF16: 45882 | AG16: 45883 | AH16: 45884 | AI16: 45885 | AJ16: 45886
B17: 11 | C17: 45796 | D17: 45797 | E17: 45798 | F17: 45799 | G17: 45800 | H17: 45801 | I17: 45802 | K17: 15 | L17: 45824 | M17: 45825 | N17: 45826 | O17: 45827 | P17: 45828 | Q17: 45829 | R17: 45830 | T17: 20 | U17: 45859 | V17: 45860 | W17: 45861 | X17: 45862 | Y17: 45863 | Z17: 45864 | AA17: 45865 | AC17: 2 | AD17: 45887 | AE17: 45888 | AF17: 45889 | AG17: 45890 | AH17: 45891 | AI17: 45892 | AJ17: 45893
B18: 12 | C18: 45803 | D18: 45804 | E18: 45805 | F18: 45806 | G18: 45807 | H18: 45808 | K18: 16 | L18: 45831 | M18: 45832 | N18: 45833 | O18: 45834 | P18: 45835 | Q18: 45836 | R18: 45837 | U18: 45866 | V18: 45867 | W18: 45868 | X18: 45869 | AC18: 3 | AD18: 45894 | AE18: 45895 | AF18: 45896 | AG18: 45897 | AH18: 45898 | AI18: 45899 | AJ18: 45900
K19: 17 | L19: 45838
B21: Semana | E21: Septiembre 2025 | K21: Semana | N21: Octubre 2025 | T21: Semana | W21: Noviembre 2025 | AC21: Semana | AF21: Diciembre 2025
C22: Lun. | D22: Mar. | E22: Mié. | F22: Jue. | G22: Vie. | H22: Sáb. | I22: Dom. | L22: Lun. | M22: Mar. | N22: Mié. | O22: Jue. | P22: Vie. | Q22: Sáb. | R22: Dom. | U22: Lun. | V22: Mar. | W22: Mié. | X22: Jue. | Y22: Vie. | Z22: Sáb. | AA22: Dom. | AD22: Lun. | AE22: Mar. | AF22: Mié. | AG22: Jue. | AH22: Vie. | AI22: Sáb. | AJ22: Dom.
B23: 4 | C23: 45901 | D23: 45902 | E23: 45903 | F23: 45904 | G23: 45905 | H23: 45906 | I23: 45907 | K23: 8 | N23: 45931 | O23: 45932 | P23: 45933 | Q23: 45934 | R23: 45935 | T23: 12 | Z23: 45962 | AA23: 45963 | AC23: 17 | AD23: 45992 | AE23: 45993 | AF23: 45994 | AG23: 45995 | AH23: 45996 | AI23: 45997 | AJ23: 45998
B24: 5 | C24: 45908 | D24: 45909 | E24: 45910 | F24: 45911 | G24: 45912 | H24: 45913 | I24: 45914 | K24: 9 | L24: 45936 | M24: 45937 | N24: 45938 | O24: 45939 | P24: 45940 | Q24: 45941 | R24: 45942 | T24: 13 | U24: 45964 | V24: 45965 | W24: 45966 | X24: 45967 | Y24: 45968 | Z24: 45969 | AA24: 45970 | AC24: 18 | AD24: 45999 | AE24: 46000 | AF24: 46001 | AG24: 46002 | AH24: 46003 | AI24: 46004 | AJ24: 46005
B25: 6 | C25: 45915 | D25: 45916 | E25: 45917 | F25: 45918 | G25: 45919 | H25: 45920 | I25: 45921 | K25: 10 | L25: 45943 | M25: 45944 | N25: 45945 | O25: 45946 | P25: 45947 | Q25: 45948 | R25: 45949 | T25: 14 | U25: 45971 | V25: 45972 | W25: 45973 | X25: 45974 | Y25: 45975 | Z25: 45976 | AA25: 45977 | AC25: 19 | AD25: 46006 | AE25: 46007 | AF25: 46008 | AG25: 46009 | AH25: 46010 | AI25: 46011 | AJ25: 46012
B26: 7 | C26: 45922 | D26: 45923 | E26: 45924 | F26: 45925 | G26: 45926 | H26: 45927 | I26: 45928 | K26: 11 | L26: 45950 | M26: 45951 | N26: 45952 | O26: 45953 | P26: 45954 | Q26: 45955 | R26: 45956 | T26: 15 | U26: 45978 | V26: 45979 | W26: 45980 | X26: 45981 | Y26: 45982 | Z26: 45983 | AA26: 45984 | AC26: 20 | AD26: 46013 | AE26: 46014 | AF26: 46015 | AG26: 46016 | AH26: 46017 | AI26: 46018 | AJ26: 46019
B27: 8 | C27: 45929 | D27: 45930 | K27: 12 | L27: 45957 | M27: 45958 | N27: 45959 | O27: 45960 | P27: 45961 | T27: 16 | U27: 45985 | V27: 45986 | W27: 45987 | X27: 45988 | Y27: 45989 | Z27: 45990 | AA27: 45991 | AD27: 46020 | AE27: 46021 | AF27: 46022
C30: SEMANA CERO | L30: PREPARACIÓN ACADÉMICA | U30: PERÍODO DE CLASES | AD30: ENCUESTA DOCENTE
C32: CIERRE SEMESTRE | L32: INSCRIPCIÓN DE ASIGNATURAS | U32: PERÍODO EXÁMENES | AD32: RECESO ACADÉMICO

Sheet CA Procesos
C2: INSTITUTO PROFESIONAL DUOC UC CALENDARIO ACADÉMICO 2027
C6: DESCRIPCIÓN | D6: TAV | F6: PRIMER SEMESTRE | H6: SEGUNDO SEMESTRE
D7: INICIO | E7: TÉRMINO | F7: INICIO | G7: TÉRMINO | H7: INICIO | I7: TÉRMINO
C8: MATRÍCULAS
C9: Período Matrícula para Estudiantes de Inicio | D9: - | E9: - | F9: 46302 | G9: 46454 | H9: - | I9: -
C10: Período Postulación para Admisión Especial Externa | D10: - | E10: - | F10: 46328 | G10: 46445 | H10: 46510 | I10: 46599
C11: Período Matrícula Admisión Especial Externa | D11: - | E11: - | F11: 46328 | G11: 46454 | H11: 46510 | I11: 46608
C12: Período Postulación Cambios Internos (Admisión Especial Interna) | D12: - | E12: - | F12: 46384 | G12: 46452 | H12: 46594 | I12: 46606
C13: Período Postulación Reincorporaciones y Reintegros | D13: - | E13: - | F13: 46328 | G13: 46452 | H13: 46545 | I13: 46606
C14: Período Matrícula Cambios Internos (Admisión Especial Interna) | D14: - | E14: - | F14: 46384 | G14: 46454 | H14: 46594 | I14: 46608
C15: Período Matrícula Reincorporaciones y Reintegros | D15: - | E15: - | F15: 46328 | G15: 46454 | H15: 46545 | I15: 46608
C16: Período Ordinario de Matrícula para Estudiantes de Continuidad | D16: - | E16: - | F16: 46357 | G16: 46396 | H16: 46569 | I16: 46592
C17: Período Extraordinario de Matrícula para Estudiantes de Continuidad | D17: - | E17: - | F17: 46398 | G17: 46454 | H17: 46594 | I17: 46608
C18: PERÍODO ACADÉMICO
C19: Período de inscripción Semestre Cero Estudiantes de Inicio | D19: - | E19: - | F19: 46314 | G19: 46444 | H19: - | I19: -
C20: Período Inducción Estudiantes de Inicio (Semana cero) | D20: - | E20: - | F20: 46447 | G20: 46452 | H20: - | I20: -
C21: Período de Preparación y Coordinación Académica | D21: - | E21: - | F21: 46447 | G21: 46452 | H21: 46601 | I21: 46606
C22: Período de Clases Temporada Académica Ordinaria | D22: - | E22: - | F22: 46454 | G22: 46588 | H22: 46608 | I22: 46742
C23: Período de Clases Temporada Académica Extraordinaria de Verano | D23: 46391 | E23: 46423 | F23: - | G23: - | H23: - | I23: -
C24: Cierre Académico y Término del Semestre | D24: 46426 | F24: 46589 | H24: 46743
C25: INSCRIPCIÓN DE ASIGNATURAS
C26: Período Ordinario de Inscripción de Asignaturas | D26: 46384 | E26: 46386 | F26: 46398 | G26: 46401 | H26: 46594 | I26: 46597
C27: Período Modificación de Carga Académica Online (Estudiantes) | D27: 46387 | E27: 46390 | F27: 46402 | G27: 46452 | H27: 46598 | I27: 46606
C28: Período Modificación de Carga Académica (Asistido) | D28: 46387 | E28: 46393 | F28: 46402 | G28: 46454 | H28: 46598 | I28: 46608
C29: Período Extraordinario de Inscripción de Asignaturas | D29: - | E29: - | F29: 46402 | G29: 46456 | H29: 46598 | I29: 46610
C30: Plazo acreditación estudiante cuidador para acceder a la prioridad de inscripción de asignatura 2027 | E30: - | F30: 46374 | H30: 46585
C31: EXAMINACIONES
C32: Período de Diagnóstico de Competencias Básicas, TICs y Test de Competencias Globales | D32: - | E32: - | F32: 46454 | G32: 46466 | H32: - | I32: -
C33: Período Extraordinario de Diagnóstico de Competencias Básicas, TICs y Test de Competencias Globales | E33: - | F33: 46475 | G33: 46480 | H33: - | I33: -
C34: Encuesta Docente | D34: - | E34: - | F34: 46531 | G34: 46550 | H34: 46685 | I34: 46704
C35: Período de Exámenes | D35: - | E35: - | F35: 46573 | G35: 46588 | H35: 46727 | I35: 46742
C36: REGLAMENTARIOS
C37: Período de Apelación para Estudiantes con Causal de Eliminación | D37: - | E37: - | F37: 46380 | G37: 46452 | H37: 46590 | I37: 46606
C38: Período para Suspensión Académica del Semestre | D38: - | E38: - | F38: 46380 | G38: 46468 | H38: 46591 | I38: 46622
C39: Período para Retiro de Asignaturas | D39: - | E39: - | F39: 46454 | G39: 46487 | H39: 46608 | I39: 46641
C40: Período para solicitud de nota pendiente (postergación de calificación) | D40: - | E40: - | F40: 46545 | G40: 46588 | H40: 46699 | I40: 46742
C41: Estado de reprobación por Inasistencia | D41: - | E41: - | F41: 46571 | H41: 46725
C42: Período para Suspensión Académica Extraordinaria del Semestre para estudiantes cuidadores | E42: - | F42: 46571 | H42: 46725
C43: PASTORAL
C44: Misiones Solidarias | D44: - | E44: - | F44: 46391 | G44: 46397 | H44: 46589 | I44: 46595
...

Sheet CA Cronológico
D2: CALENDARIO ACADÉMICO 2027
D4: TAV | E4: INICIO | F4: TÉRMINO
D5: Feriado Año Nuevo | E5: ='CA Procesos'!F50 -> 46388
D6: Período Ordinario de Inscripción de Asignaturas | E6: ='CA Procesos'!D26 -> 46384 | F6: ='CA Procesos'!E26 -> 46386
D7: Período Modificación de Carga Académica Online (Estudiantes) | E7: ='CA Procesos'!D27 -> 46387 | F7: ='CA Procesos'!E27 -> 46390
D8: Período Modificación de Carga Académica (Asistido) | E8: ='CA Procesos'!D28 -> 46387 | F8: ='CA Procesos'!E28 -> 46393
D9: Período de Clases Temporada Académica Ordinaria de Verano | E9: ='CA Procesos'!D23 -> 46391 | F9: ='CA Procesos'!E23 -> 46423
D10: Cierre Académico y Término del Semestre | E10: ='CA Procesos'!D24 -> 46426
D12: 1er SEMESTRE / 2027-1 | E12: INICIO | F12: TÉRMINO
D13: Período Matrícula para Estudiantes de Inicio | E13: ='CA Procesos'!F9 -> 46302 | F13: ='CA Procesos'!G9 -> 46454
D14: Período Postulación para Admisión Especial Externa | E14: ='CA Procesos'!F10 -> 46328 | F14: ='CA Procesos'!G10 -> 46445
D15: Período Matrícula Admisión Especial Externa | E15: ='CA Procesos'!F11 -> 46328 | F15: ='CA Procesos'!G11 -> 46454
D16: Período Postulación Reincorporaciones y Reintegros | E16: ='CA Procesos'!F13 -> 46328 | F16: ='CA Procesos'!G13 -> 46452
D17: Período Matrícula Reincorporaciones y Reintegros | E17: ='CA Procesos'!F15 -> 46328 | F17: ='CA Procesos'!G15 -> 46454
D18: Período Ordinario de Matrícula para Estudiantes de Continuidad | E18: ='CA Procesos'!F16 -> 46357 | F18: ='CA Procesos'!G16 -> 46396
D19: Período de Inscripción Semestre Cero Estudiantes de Inicio | E19: ='CA Procesos'!F19 -> 46314 | F19: ='CA Procesos'!G19 -> 46444
D20: Período para Suspensión Académica del Semestre | E20: ='CA Procesos'!F38 -> 46380 | F20: ='CA Procesos'!G38 -> 46468
D21: Período de Apelación para Estudiantes con Causal de Eliminación | E21: ='CA Procesos'!F37 -> 46380 | F21: ='CA Procesos'!G37 -> 46452
D22: Período Postulación Cambios Internos (Admisión Especial Interna) | E22: ='CA Procesos'!F12 -> 46384 | F22: ='CA Procesos'!G12 -> 46452
D23: Período Matrícula Cambios Internos (Admisión Especial Interna) | E23: ='CA Procesos'!F14 -> 46384 | F23: ='CA Procesos'!G14 -> 46454
D24: Misiones Solidarias | E24: ='CA Procesos'!F44 -> 46391 | F24: ='CA Procesos'!G44 -> 46397
D25: Período Extraordinario de Matrícula para Estudiantes de Continuidad | E25: ='CA Procesos'!F17 -> 46398 | F25: ='CA Procesos'!G17 -> 46454
D26: Período Ordinario de Inscripción de Asignaturas | E26: ='CA Procesos'!F26 -> 46398 | F26: ='CA Procesos'!G26 -> 46401
D27: Período Modificación de Carga Académica Online (Estudiantes) | E27: ='CA Procesos'!F27 -> 46402 | F27: ='CA Procesos'!G27 -> 46452
D28: Período Modificación de Carga Académica (Asistido) | E28: ='CA Procesos'!F28 -> 46402 | F28: ='CA Procesos'!G28 -> 46454
D29: Período Extraordinario de Inscripción de Asignaturas | E29: ='CA Procesos'!F29 -> 46402 | F29: ='CA Procesos'!G29 -> 46456
D30: Período Inducción Estudiantes de Inicio (Semana cero) | E30: ='CA Procesos'!F20 -> 46447 | F30: ='CA Procesos'!G20 -> 46452
D31: Período de Preparación y Coordinación Académica | E31: ='CA Procesos'!F21 -> 46447 | F31: ='CA Procesos'!G21 -> 46452
D32: Período de Clases Temporada Académica Ordinaria | E32: ='CA Procesos'!F22 -> 46454 | F32: ='CA Procesos'!G22 -> 46588
D33: Período de Diagnóstico de Competencias Básicas, TICs y Test de Competencias Globales | E33: ='CA Procesos'!F32 -> 46454 | F33: ='CA Procesos'!G32 -> 46466
D34: Período para Retiro de Asignaturas | E34: ='CA Procesos'!F39 -> 46454 | F34: ='CA Procesos'!G39 -> 46487
D35: Período Extraordinario de Diagnóstico de Competencias Básicas, TICs y Test de Competencias Globales | E35: ='CA Procesos'!F33 -> 46475 | F35: ='CA Procesos'!G33 -> 46480
D36: Víspera de Feriado Semana Santa - Media Jornada Académica (13:00 hrs) | E36: ='CA Procesos'!F51 -> 46471
D37: Feriado Semana Santa (Viernes Santo y Sábado Santo) | E37: ='CA Procesos'!F52 -> 46472 | F37: ='CA Procesos'!G52 -> 46473
D38: Semana de asesoría académica y progresión | E38: ='CA Procesos'!F46 -> 46482 | F38: ='CA Procesos'!G46 -> 46487
D39: Elección de Consejeros de Carrera | E39: ='CA Procesos'!F47 -> 46491 | F39: ='CA Procesos'!G47 -> 46494
D40: Investiduras Consejeros de Carrera | E40: ='CA Procesos'!F48 -> 46503 | F40: ='CA Procesos'!G48 -> 46508
D41: Feriado Día del Trabajador | E41: ='CA Procesos'!F53 -> 46508
D42: Feriado Día de las Glorias Navales | E42: ='CA Procesos'!F54 -> 46528
D43: Encuesta Docente | E43: ='CA Procesos'!F34 -> 46531 | F43: ='CA Procesos'!G34 -> 46550
...

Sheet CA Gráfico 2027
F2: Año | G2: 2027 | L2: Mes | M2: 1 | S2: Día de inicio | T2: 2 | W2: 1:Dom, 2:Lun...
D5: INSTITUTO PROFESIONAL DUOC UC CALENDARIO ACADÉMICO 2027
D9: Semana | E9: =DATE(G2,M2,1) -> 46388 | L9: Semana | M9: =DATE(YEAR(E9+42),MONTH(E9+42),1) -> 46419 | T9: Semana | U9: =DATE(YEAR(M9+42),MONTH(M9+42),1) -> 46447 | AB9: Semana | AC9: =DATE(YEAR(U9+42),MONTH(U9+42),1) -> 46478
E10: =CHOOSE(1+MOD($T$2+1-2,7),"D","L","M","M","J","V","S") -> L | F10: =CHOOSE(1+MOD($T$2+2-2,7),"D","L","M","M","J","V","S") -> M | G10: =CHOOSE(1+MOD($T$2+3-2,7),"D","L","M","M","J","V","S") -> M | H10: =CHOOSE(1+MOD($T$2+4-2,7),"D","L","M","M","J","V","S") -> J | I10: =CHOOSE(1+MOD($T$2+5-2,7),"D","L","M","M","J","V","S") -> V | J10: =CHOOSE(1+MOD($T$2+6-2,7),"D","L","M","M","J","V","S") -> S | K10: =CHOOSE(1+MOD($T$2+7-2,7),"D","L","M","M","J","V","S") -> D | M10: =CHOOSE(1+MOD($T$2+1-2,7),"D","L","M","M","J","V","S") -> L | N10: =CHOOSE(1+MOD($T$2+2-2,7),"D","L","M","M","J","V","S") -> M | O10: =CHOOSE(1+MOD($T$2+3-2,7),"D","L","M","M","J","V","S") -> M | P10: =CHOOSE(1+MOD($T$2+4-2,7),"D","L","M","M","J","V","S") -> J | Q10: =CHOOSE(1+MOD($T$2+5-2,7),"D","L","M","M","J","V","S") -> V | R10: =CHOOSE(1+MOD($T$2+6-2,7),"D","L","M","M","J","V","S") -> S | S10: =CHOOSE(1+MOD($T$2+7-2,7),"D","L","M","M","J","V","S") -> D | U10: =CHOOSE(1+MOD($T$2+1-2,7),"D","L","M","M","J","V","S") -> L | V10: =CHOOSE(1+MOD($T$2+2-2,7),"D","L","M","M","J","V","S") -> M | W10: =CHOOSE(1+MOD($T$2+3-2,7),"D","L","M","M","J","V","S") -> M | X10: =CHOOSE(1+MOD($T$2+4-2,7),"D","L","M","M","J","V","S") -> J | Y10: =CHOOSE(1+MOD($T$2+5-2,7),"D","L","M","M","J","V","S") -> V | Z10: =CHOOSE(1+MOD($T$2+6-2,7),"D","L","M","M","J","V","S") -> S | AA10: =CHOOSE(1+MOD($T$2+7-2,7),"D","L","M","M","J","V","S") -> D | AC10: =CHOOSE(1+MOD($T$2+1-2,7),"D","L","M","M","J","V","S") -> L | AD10: =CHOOSE(1+MOD($T$2+2-2,7),"D","L","M","M","J","V","S") -> M | AE10: =CHOOSE(1+MOD($T$2+3-2,7),"D","L","M","M","J","V","S") -> M | AF10: =CHOOSE(1+MOD($T$2+4-2,7),"D","L","M","M","J","V","S") -> J | AG10: =CHOOSE(1+MOD($T$2+5-2,7),"D","L","M","M","J","V","S") -> V | AH10: =CHOOSE(1+MOD($T$2+6-2,7),"D","L","M","M","J","V","S") -> S | AI10: =CHOOSE(1+MOD($T$2+7-2,7),"D","L","M","M","J","V","S") -> D
E11: =IF(WEEKDAY(E9,1)=MOD($T$2-1,7)+1,E9,"") | F11: =IF(E11="",IF(WEEKDAY(E9,1)=MOD($T$2,7)+1,E9,""),E11+1) | G11: =IF(F11="",IF(WEEKDAY(E9,1)=MOD($T$2+1,7)+1,E9,""),F11+1) | H11: =IF(G11="",IF(WEEKDAY(E9,1)=MOD($T$2+2,7)+1,E9,""),G11+1) | I11: =IF(H11="",IF(WEEKDAY(E9,1)=MOD($T$2+3,7)+1,E9,""),H11+1) -> 46388 | J11: =IF(I11="",IF(WEEKDAY(E9,1)=MOD($T$2+4,7)+1,E9,""),I11+1) -> 46389 | K11: =IF(J11="",IF(WEEKDAY(E9,1)=MOD($T$2+5,7)+1,E9,""),J11+1) -> 46390 | L11: 5 | M11: =IF(WEEKDAY(M9,1)=MOD($T$2-1,7)+1,M9,"") -> 46419 | N11: =IF(M11="",IF(WEEKDAY(M9,1)=MOD($T$2,7)+1,M9,""),M11+1) -> 46420 | O11: =IF(N11="",IF(WEEKDAY(M9,1)=MOD($T$2+1,7)+1,M9,""),N11+1) -> 46421 | P11: =IF(O11="",IF(WEEKDAY(M9,1)=MOD($T$2+2,7)+1,M9,""),O11+1) -> 46422 | Q11: =IF(P11="",IF(WEEKDAY(M9,1)=MOD($T$2+3,7)+1,M9,""),P11+1) -> 46423 | R11: =IF(Q11="",IF(WEEKDAY(M9,1)=MOD($T$2+4,7)+1,M9,""),Q11+1) -> 46424 | S11: =IF(R11="",IF(WEEKDAY(M9,1)=MOD($T$2+5,7)+1,M9,""),R11+1) -> 46425 | U11: =IF(WEEKDAY(U9,1)=MOD($T$2-1,7)+1,U9,"") -> 46447 | V11: =IF(U11="",IF(WEEKDAY(U9,1)=MOD($T$2,7)+1,U9,""),U11+1) -> 46448 | W11: =IF(V11="",IF(WEEKDAY(U9,1)=MOD($T$2+1,7)+1,U9,""),V11+1) -> 46449 | X11: =IF(W11="",IF(WEEKDAY(U9,1)=MOD($T$2+2,7)+1,U9,""),W11+1) -> 46450 | Y11: =IF(X11="",IF(WEEKDAY(U9,1)=MOD($T$2+3,7)+1,U9,""),X11+1) -> 46451 | Z11: =IF(Y11="",IF(WEEKDAY(U9,1)=MOD($T$2+4,7)+1,U9,""),Y11+1) -> 46452 | AA11: =IF(Z11="",IF(WEEKDAY(U9,1)=MOD($T$2+5,7)+1,U9,""),Z11+1) -> 46453 | AB11: 4 | AC11: =IF(WEEKDAY(AC9,1)=MOD($T$2-1,7)+1,AC9,"") | AD11: =IF(AC11="",IF(WEEKDAY(AC9,1)=MOD($T$2,7)+1,AC9,""),AC11+1) | AE11: =IF(AD11="",IF(WEEKDAY(AD9,1)=MOD($T$2,7)+1,AD9,""),AD11+1) | AF11: =IF(AE11="",IF(WEEKDAY(AC9,1)=MOD($T$2+2,7)+1,AC9,""),AE11+1) -> 46478 | AG11: =IF(AF11="",IF(WEEKDAY(AC9,1)=MOD($T$2+3,7)+1,AC9,""),AF11+1) -> 46479 | AH11: =IF(AG11="",IF(WEEKDAY(AC9,1)=MOD($T$2+4,7)+1,AC9,""),AG11+1) -> 46480 | AI11: =IF(AH11="",IF(WEEKDAY(AC9,1)=MOD($T$2+5,7)+1,AC9,""),AH11+1) -> 46481
D12: 1 | E12: =IF(K11="","",IF(MONTH(K11+1)<>MONTH(K11),"",K11+1)) -> 46391 | F12: =IF(E12="","",IF(MONTH(E12+1)<>MONTH(E12),"",E12+1)) -> 46392 | G12: =IF(F12="","",IF(MONTH(F12+1)<>MONTH(F12),"",F12+1)) -> 46393 | H12: =IF(G12="","",IF(MONTH(G12+1)<>MONTH(G12),"",G12+1)) -> 46394 | I12: =IF(H12="","",IF(MONTH(H12+1)<>MONTH(H12),"",H12+1)) -> 46395 | J12: =IF(I12="","",IF(MONTH(I12+1)<>MONTH(I12),"",I12+1)) -> 46396 | K12: =IF(J12="","",IF(MONTH(J12+1)<>MONTH(J12),"",J12+1)) -> 46397 | L12: 6 | M12: =IF(S11="","",IF(MONTH(S11+1)<>MONTH(S11),"",S11+1)) -> 46426 | N12: =IF(M12="","",IF(MONTH(M12+1)<>MONTH(M12),"",M12+1)) -> 46427 | O12: =IF(N12="","",IF(MONTH(N12+1)<>MONTH(N12),"",N12+1)) -> 46428 | P12: =IF(O12="","",IF(MONTH(O12+1)<>MONTH(O12),"",O12+1)) -> 46429 | Q12: =IF(P12="","",IF(MONTH(P12+1)<>MONTH(P12),"",P12+1)) -> 46430 | R12: =IF(Q12="","",IF(MONTH(Q12+1)<>MONTH(Q12),"",Q12+1)) -> 46431 | S12: =IF(R12="","",IF(MONTH(R12+1)<>MONTH(R12),"",R12+1)) -> 46432 | T12: 1 | U12: =IF(AA11="","",IF(MONTH(AA11+1)<>MONTH(AA11),"",AA11+1)) -> 46454 | V12: =IF(U12="","",IF(MONTH(U12+1)<>MONTH(U12),"",U12+1)) -> 46455 | W12: =IF(V12="","",IF(MONTH(V12+1)<>MONTH(V12),"",V12+1)) -> 46456 | X12: =IF(W12="","",IF(MONTH(W12+1)<>MONTH(W12),"",W12+1)) -> 46457 | Y12: =IF(X12="","",IF(MONTH(X12+1)<>MONTH(X12),"",X12+1)) -> 46458 | Z12: =IF(Y12="","",IF(MONTH(Y12+1)<>MONTH(Y12),"",Y12+1)) -> 46459 | AA12: =IF(Z12="","",IF(MONTH(Z12+1)<>MONTH(Z12),"",Z12+1)) -> 46460 | AB12: 5 | AC12: =IF(AI11="","",IF(MONTH(AI11+1)<>MONTH(AI11),"",AI11+1)) -> 46482 | AD12: =IF(AC12="","",IF(MONTH(AC12+1)<>MONTH(AC12),"",AC12+1)) -> 46483 | AE12: =IF(AD12="","",IF(MONTH(AD12+1)<>MONTH(AD12),"",AD12+1)) -> 46484 | AF12: =IF(AE12="","",IF(MONTH(AE12+1)<>MONTH(AE12),"",AE12+1)) -> 46485 | AG12: =IF(AF12="","",IF(MONTH(AF12+1)<>MONTH(AF12),"",AF12+1)) -> 46486 | AH12: =IF(AG12="","",IF(MONTH(AG12+1)<>MONTH(AG12),"",AG12+1)) -> 46487 | AI12: =IF(AH12="","",IF(MONTH(AH12+1)<>MONTH(AH12),"",AH12+1)) -> 46488
D13: 2 | E13: =IF(K12="","",IF(MONTH(K12+1)<>MONTH(K12),"",K12+1)) -> 46398 | F13: =IF(E13="","",IF(MONTH(E13+1)<>MONTH(E13),"",E13+1)) -> 46399 | G13: =IF(F13="","",IF(MONTH(F13+1)<>MONTH(F13),"",F13+1)) -> 46400 | H13: =IF(G13="","",IF(MONTH(G13+1)<>MONTH(G13),"",G13+1)) -> 46401 | I13: =IF(H13="","",IF(MONTH(H13+1)<>MONTH(H13),"",H13+1)) -> 46402 | J13: =IF(I13="","",IF(MONTH(I13+1)<>MONTH(I13),"",I13+1)) -> 46403 | K13: =IF(J13="","",IF(MONTH(J13+1)<>MONTH(J13),"",J13+1)) -> 46404 | M13: =IF(S12="","",IF(MONTH(S12+1)<>MONTH(S12),"",S12+1)) -> 46433 | N13: =IF(M13="","",IF(MONTH(M13+1)<>MONTH(M13),"",M13+1)) -> 46434 | O13: =IF(N13="","",IF(MONTH(N13+1)<>MONTH(N13),"",N13+1)) -> 46435 | P13: =IF(O13="","",IF(MONTH(O13+1)<>MONTH(O13),"",O13+1)) -> 46436 | Q13: =IF(P13="","",IF(MONTH(P13+1)<>MONTH(P13),"",P13+1)) -> 46437 | R13: =IF(Q13="","",IF(MONTH(Q13+1)<>MONTH(Q13),"",Q13+1)) -> 46438 | S13: =IF(R13="","",IF(MONTH(R13+1)<>MONTH(R13),"",R13+1)) -> 46439 | T13: 2 | U13: =IF(AA12="","",IF(MONTH(AA12+1)<>MONTH(AA12),"",AA12+1)) -> 46461 | V13: =IF(U13="","",IF(MONTH(U13+1)<>MONTH(U13),"",U13+1)) -> 46462 | W13: =IF(V13="","",IF(MONTH(V13+1)<>MONTH(V13),"",V13+1)) -> 46463 | X13: =IF(W13="","",IF(MONTH(W13+1)<>MONTH(W13),"",W13+1)) -> 46464 | Y13: =IF(X13="","",IF(MONTH(X13+1)<>MONTH(X13),"",X13+1)) -> 46465 | Z13: =IF(Y13="","",IF(MONTH(Y13+1)<>MONTH(Y13),"",Y13+1)) -> 46466 | AA13: =IF(Z13="","",IF(MONTH(Z13+1)<>MONTH(Z13),"",Z13+1)) -> 46467 | AB13: 6 | AC13: =IF(AI12="","",IF(MONTH(AI12+1)<>MONTH(AI12),"",AI12+1)) -> 46489 | AD13: =IF(AC13="","",IF(MONTH(AC13+1)<>MONTH(AC13),"",AC13+1)) -> 46490 | AE13: =IF(AD13="","",IF(MONTH(AD13+1)<>MONTH(AD13),"",AD13+1)) -> 46491 | AF13: =IF(AE13="","",IF(MONTH(AE13+1)<>MONTH(AE13),"",AE13+1)) -> 46492 | AG13: =IF(AF13="","",IF(MONTH(AF13+1)<>MONTH(AF13),"",AF13+1)) -> 46493 | AH13: =IF(AG13="","",IF(MONTH(AG13+1)<>MONTH(AG13),"",AG13+1)) -> 46494 | AI13: =IF(AH13="","",IF(MONTH(AH13+1)<>MONTH(AH13),"",AH13+1)) -> 46495
D14: 3 | E14: =IF(K13="","",IF(MONTH(K13+1)<>MONTH(K13),"",K13+1)) -> 46405 | F14: =IF(E14="","",IF(MONTH(E14+1)<>MONTH(E14),"",E14+1)) -> 46406 | G14: =IF(F14="","",IF(MONTH(F14+1)<>MONTH(F14),"",F14+1)) -> 46407 | H14: =IF(G14="","",IF(MONTH(G14+1)<>MONTH(G14),"",G14+1)) -> 46408 | I14: =IF(H14="","",IF(MONTH(H14+1)<>MONTH(H14),"",H14+1)) -> 46409 | J14: =IF(I14="","",IF(MONTH(I14+1)<>MONTH(I14),"",I14+1)) -> 46410 | K14: =IF(J14="","",IF(MONTH(J14+1)<>MONTH(J14),"",J14+1)) -> 46411 | M14: =IF(S13="","",IF(MONTH(S13+1)<>MONTH(S13),"",S13+1)) -> 46440 | N14: =IF(M14="","",IF(MONTH(M14+1)<>MONTH(M14),"",M14+1)) -> 46441 | O14: =IF(N14="","",IF(MONTH(N14+1)<>MONTH(N14),"",N14+1)) -> 46442 | P14: =IF(O14="","",IF(MONTH(O14+1)<>MONTH(O14),"",O14+1)) -> 46443 | Q14: =IF(P14="","",IF(MONTH(P14+1)<>MONTH(P14),"",P14+1)) -> 46444 | R14: =IF(Q14="","",IF(MONTH(Q14+1)<>MONTH(Q14),"",Q14+1)) -> 46445 | S14: =IF(R14="","",IF(MONTH(R14+1)<>MONTH(R14),"",R14+1)) -> 46446 | T14: 3 | U14: =IF(AA13="","",IF(MONTH(AA13+1)<>MONTH(AA13),"",AA13+1)) -> 46468 | V14: =IF(U14="","",IF(MONTH(U14+1)<>MONTH(U14),"",U14+1)) -> 46469 | W14: =IF(V14="","",IF(MONTH(V14+1)<>MONTH(V14),"",V14+1)) -> 46470 | X14: =IF(W14="","",IF(MONTH(W14+1)<>MONTH(W14),"",W14+1)) -> 46471 | Y14: =IF(X14="","",IF(MONTH(X14+1)<>MONTH(X14),"",X14+1)) -> 46472 | Z14: =IF(Y14="","",IF(MONTH(Y14+1)<>MONTH(Y14),"",Y14+1)) -> 46473 | AA14: =IF(Z14="","",IF(MONTH(Z14+1)<>MONTH(Z14),"",Z14+1)) -> 46474 | AB14: 7 | AC14: =IF(AI13="","",IF(MONTH(AI13+1)<>MONTH(AI13),"",AI13+1)) -> 46496 | AD14: =IF(AC14="","",IF(MONTH(AC14+1)<>MONTH(AC14),"",AC14+1)) -> 46497 | AE14: =IF(AD14="","",IF(MONTH(AD14+1)<>MONTH(AD14),"",AD14+1)) -> 46498 | AF14: =IF(AE14="","",IF(MONTH(AE14+1)<>MONTH(AE14),"",AE14+1)) -> 46499 | AG14: =IF(AF14="","",IF(MONTH(AF14+1)<>MONTH(AF14),"",AF14+1)) -> 46500 | AH14: =IF(AG14="","",IF(MONTH(AG14+1)<>MONTH(AG14),"",AG14+1)) -> 46501 | AI14: =IF(AH14="","",IF(MONTH(AH14+1)<>MONTH(AH14),"",AH14+1)) -> 46502
D15: 4 | E15: =IF(K14="","",IF(MONTH(K14+1)<>MONTH(K14),"",K14+1)) -> 46412 | F15: =IF(E15="","",IF(MONTH(E15+1)<>MONTH(E15),"",E15+1)) -> 46413 | G15: =IF(F15="","",IF(MONTH(F15+1)<>MONTH(F15),"",F15+1)) -> 46414 | H15: =IF(G15="","",IF(MONTH(G15+1)<>MONTH(G15),"",G15+1)) -> 46415 | I15: =IF(H15="","",IF(MONTH(H15+1)<>MONTH(H15),"",H15+1)) -> 46416 | J15: =IF(I15="","",IF(MONTH(I15+1)<>MONTH(I15),"",I15+1)) -> 46417 | K15: =IF(J15="","",IF(MONTH(J15+1)<>MONTH(J15),"",J15+1)) -> 46418 | M15: =IF(S14="","",IF(MONTH(S14+1)<>MONTH(S14),"",S14+1)) | N15: =IF(M15="","",IF(MONTH(M15+1)<>MONTH(M15),"",M15+1)) | O15: =IF(N15="","",IF(MONTH(N15+1)<>MONTH(N15),"",N15+1)) | P15: =IF(O15="","",IF(MONTH(O15+1)<>MONTH(O15),"",O15+1)) | Q15: =IF(P15="","",IF(MONTH(P15+1)<>MONTH(P15),"",P15+1)) | R15: =IF(Q15="","",IF(MONTH(Q15+1)<>MONTH(Q15),"",Q15+1)) | S15: =IF(R15="","",IF(MONTH(R15+1)<>MONTH(R15),"",R15+1)) | T15: 4 | U15: =IF(AA14="","",IF(MONTH(AA14+1)<>MONTH(AA14),"",AA14+1)) -> 46475 | V15: =IF(U15="","",IF(MONTH(U15+1)<>MONTH(U15),"",U15+1)) -> 46476 | W15: =IF(V15="","",IF(MONTH(V15+1)<>MONTH(V15),"",V15+1)) -> 46477 | X15: =IF(W15="","",IF(MONTH(W15+1)<>MONTH(W15),"",W15+1)) | Y15: =IF(X15="","",IF(MONTH(X15+1)<>MONTH(X15),"",X15+1)) | Z15: =IF(Y15="","",IF(MONTH(Y15+1)<>MONTH(Y15),"",Y15+1)) | AA15: =IF(Z15="","",IF(MONTH(Z15+1)<>MONTH(Z15),"",Z15+1)) | AB15: 8 | AC15: =IF(AI14="","",IF(MONTH(AI14+1)<>MONTH(AI14),"",AI14+1)) -> 46503 | AD15: =IF(AC15="","",IF(MONTH(AC15+1)<>MONTH(AC15),"",AC15+1)) -> 46504 | AE15: =IF(AD15="","",IF(MONTH(AD15+1)<>MONTH(AD15),"",AD15+1)) -> 46505 | AF15: =IF(AE15="","",IF(MONTH(AE15+1)<>MONTH(AE15),"",AE15+1)) -> 46506 | AG15: =IF(AF15="","",IF(MONTH(AF15+1)<>MONTH(AF15),"",AF15+1)) -> 46507 | AH15: =IF(AG15="","",IF(MONTH(AG15+1)<>MONTH(AG15),"",AG15+1)) | AI15: =IF(AH15="","",IF(MONTH(AH15+1)<>MONTH(AH15),"",AH15+1))
E16: =IF(K15="","",IF(MONTH(K15+1)<>MONTH(K15),"",K15+1)) | F16: =IF(E16="","",IF(MONTH(E16+1)<>MONTH(E16),"",E16+1)) | G16: =IF(F16="","",IF(MONTH(F16+1)<>MONTH(F16),"",F16+1)) | H16: =IF(G16="","",IF(MONTH(G16+1)<>MONTH(G16),"",G16+1)) | I16: =IF(H16="","",IF(MONTH(H16+1)<>MONTH(H16),"",H16+1)) | J16: =IF(I16="","",IF(MONTH(I16+1)<>MONTH(I16),"",I16+1)) | K16: =IF(J16="","",IF(MONTH(J16+1)<>MONTH(J16),"",J16+1)) | M16: =IF(S15="","",IF(MONTH(S15+1)<>MONTH(S15),"",S15+1)) | N16: =IF(M16="","",IF(MONTH(M16+1)<>MONTH(M16),"",M16+1)) | O16: =IF(N16="","",IF(MONTH(N16+1)<>MONTH(N16),"",N16+1)) | P16: =IF(O16="","",IF(MONTH(O16+1)<>MONTH(O16),"",O16+1)) | Q16: =IF(P16="","",IF(MONTH(P16+1)<>MONTH(P16),"",P16+1)) | R16: =IF(Q16="","",IF(MONTH(Q16+1)<>MONTH(Q16),"",Q16+1)) | S16: =IF(R16="","",IF(MONTH(R16+1)<>MONTH(R16),"",R16+1)) | AC16: =IF(AI15="","",IF(MONTH(AI15+1)<>MONTH(AI15),"",AI15+1)) | AD16: =IF(AC16="","",IF(MONTH(AC16+1)<>MONTH(AC16),"",AC16+1)) | AE16: =IF(AD16="","",IF(MONTH(AD16+1)<>MONTH(AD16),"",AD16+1)) | AF16: =IF(AE16="","",IF(MONTH(AE16+1)<>MONTH(AE16),"",AE16+1)) | AG16: =IF(AF16="","",IF(MONTH(AF16+1)<>MONTH(AF16),"",AF16+1)) | AH16: =IF(AG16="","",IF(MONTH(AG16+1)<>MONTH(AG16),"",AG16+1)) | AI16: =IF(AH16="","",IF(MONTH(AH16+1)<>MONTH(AH16),"",AH16+1))
D20: Semana | E20: =DATE(YEAR(AC9+42),MONTH(AC9+42),1) -> 46508 | L20: Semana | M20: =DATE(YEAR(E20+42),MONTH(E20+42),1) -> 46539 | T20: Semana | U20: =DATE(YEAR(M20+42),MONTH(M20+42),1) -> 46569 | AB20: Semana | AC20: =DATE(YEAR(U20+42),MONTH(U20+42),1) -> 46600
E21: =CHOOSE(1+MOD($T$2+1-2,7),"D","L","M","M","J","V","S") -> L | F21: =CHOOSE(1+MOD($T$2+2-2,7),"D","L","M","M","J","V","S") -> M | G21: =CHOOSE(1+MOD($T$2+3-2,7),"D","L","M","M","J","V","S") -> M | H21: =CHOOSE(1+MOD($T$2+4-2,7),"D","L","M","M","J","V","S") -> J | I21: =CHOOSE(1+MOD($T$2+5-2,7),"D","L","M","M","J","V","S") -> V | J21: =CHOOSE(1+MOD($T$2+6-2,7),"D","L","M","M","J","V","S") -> S | K21: =CHOOSE(1+MOD($T$2+7-2,7),"D","L","M","M","J","V","S") -> D | M21: =CHOOSE(1+MOD($T$2+1-2,7),"D","L","M","M","J","V","S") -> L | N21: =CHOOSE(1+MOD($T$2+2-2,7),"D","L","M","M","J","V","S") -> M | O21: =CHOOSE(1+MOD($T$2+3-2,7),"D","L","M","M","J","V","S") -> M | P21: =CHOOSE(1+MOD($T$2+4-2,7),"D","L","M","M","J","V","S") -> J | Q21: =CHOOSE(1+MOD($T$2+5-2,7),"D","L","M","M","J","V","S") -> V | R21: =CHOOSE(1+MOD($T$2+6-2,7),"D","L","M","M","J","V","S") -> S | S21: =CHOOSE(1+MOD($T$2+7-2,7),"D","L","M","M","J","V","S") -> D | U21: =CHOOSE(1+MOD($T$2+1-2,7),"D","L","M","M","J","V","S") -> L | V21: =CHOOSE(1+MOD($T$2+2-2,7),"D","L","M","M","J","V","S") -> M | W21: =CHOOSE(1+MOD($T$2+3-2,7),"D","L","M","M","J","V","S") -> M | X21: =CHOOSE(1+MOD($T$2+4-2,7),"D","L","M","M","J","V","S") -> J | Y21: =CHOOSE(1+MOD($T$2+5-2,7),"D","L","M","M","J","V","S") -> V | Z21: =CHOOSE(1+MOD($T$2+6-2,7),"D","L","M","M","J","V","S") -> S | AA21: =CHOOSE(1+MOD($T$2+7-2,7),"D","L","M","M","J","V","S") -> D | AC21: =CHOOSE(1+MOD($T$2+1-2,7),"D","L","M","M","J","V","S") -> L | AD21: =CHOOSE(1+MOD($T$2+2-2,7),"D","L","M","M","J","V","S") -> M | AE21: =CHOOSE(1+MOD($T$2+3-2,7),"D","L","M","M","J","V","S") -> M | AF21: =CHOOSE(1+MOD($T$2+4-2,7),"D","L","M","M","J","V","S") -> J | AG21: =CHOOSE(1+MOD($T$2+5-2,7),"D","L","M","M","J","V","S") -> V | AH21: =CHOOSE(1+MOD($T$2+6-2,7),"D","L","M","M","J","V","S") -> S | AI21: =CHOOSE(1+MOD($T$2+7-2,7),"D","L","M","M","J","V","S") -> D
D22: 8 | E22: =IF(WEEKDAY(E20,1)=MOD($T$2-1,7)+1,E20,"") | F22: =IF(E22="",IF(WEEKDAY(E20,1)=MOD($T$2,7)+1,E20,""),E22+1) | G22: =IF(F22="",IF(WEEKDAY(E20,1)=MOD($T$2+1,7)+1,E20,""),F22+1) | H22: =IF(G22="",IF(WEEKDAY(E20,1)=MOD($T$2+2,7)+1,E20,""),G22+1) | I22: =IF(H22="",IF(WEEKDAY(F20,1)=MOD($T$2+2,7)+1,F20,""),H22+1) | J22: =IF(I22="",IF(WEEKDAY(E20,1)=MOD($T$2+4,7)+1,E20,""),I22+1) -> 46508 | K22: =IF(J22="",IF(WEEKDAY(E20,1)=MOD($T$2+5,7)+1,E20,""),J22+1) -> 46509 | L22: 13 | M22: =IF(WEEKDAY(M20,1)=MOD($T$2-1,7)+1,M20,"") | N22: =IF(M22="",IF(WEEKDAY(M20,1)=MOD($T$2,7)+1,M20,""),M22+1) -> 46539 | O22: =IF(N22="",IF(WEEKDAY(M20,1)=MOD($T$2+1,7)+1,M20,""),N22+1) -> 46540 | P22: =IF(O22="",IF(WEEKDAY(M20,1)=MOD($T$2+2,7)+1,M20,""),O22+1) -> 46541 | Q22: =IF(P22="",IF(WEEKDAY(M20,1)=MOD($T$2+3,7)+1,M20,""),P22+1) -> 46542 | R22: =IF(Q22="",IF(WEEKDAY(M20,1)=MOD($T$2+4,7)+1,M20,""),Q22+1) -> 46543 | S22: =IF(R22="",IF(WEEKDAY(M20,1)=MOD($T$2+5,7)+1,M20,""),R22+1) -> 46544 | T22: 17 | U22: =IF(WEEKDAY(U20,1)=MOD($T$2-1,7)+1,U20,"") | V22: =IF(U22="",IF(WEEKDAY(U20,1)=MOD($T$2,7)+1,U20,""),U22+1) | W22: =IF(V22="",IF(WEEKDAY(U20,1)=MOD($T$2+1,7)+1,U20,""),V22+1) | X22: =IF(W22="",IF(WEEKDAY(U20,1)=MOD($T$2+2,7)+1,U20,""),W22+1) -> 46569 | Y22: =IF(X22="",IF(WEEKDAY(U20,1)=MOD($T$2+3,7)+1,U20,""),X22+1) -> 46570 | Z22: =IF(Y22="",IF(WEEKDAY(U20,1)=MOD($T$2+4,7)+1,U20,""),Y22+1) -> 46571 | AA22: =IF(Z22="",IF(WEEKDAY(U20,1)=MOD($T$2+5,7)+1,U20,""),Z22+1) -> 46572 | AC22: =IF(WEEKDAY(AC20,1)=MOD($T$2-1,7)+1,AC20,"") | AD22: =IF(AC22="",IF(WEEKDAY(AC20,1)=MOD($T$2,7)+1,AC20,""),AC22+1) | AE22: =IF(AD22="",IF(WEEKDAY(AC20,1)=MOD($T$2+1,7)+1,AC20,""),AD22+1) | AF22: =IF(AE22="",IF(WEEKDAY(AC20,1)=MOD($T$2+2,7)+1,AC20,""),AE22+1) | AG22: =IF(AF22="",IF(WEEKDAY(AC20,1)=MOD($T$2+3,7)+1,AC20,""),AF22+1) | AH22: =IF(AG22="",IF(WEEKDAY(AC20,1)=MOD($T$2+4,7)+1,AC20,""),AG22+1) | AI22: =IF(AH22="",IF(WEEKDAY(AC20,1)=MOD($T$2+5,7)+1,AC20,""),AH22+1) -> 46600
D23: 9 | E23: =IF(K22="","",IF(MONTH(K22+1)<>MONTH(K22),"",K22+1)) -> 46510 | F23: =IF(E23="","",IF(MONTH(E23+1)<>MONTH(E23),"",E23+1)) -> 46511 | G23: =IF(F23="","",IF(MONTH(F23+1)<>MONTH(F23),"",F23+1)) -> 46512 | H23: =IF(G23="","",IF(MONTH(G23+1)<>MONTH(G23),"",G23+1)) -> 46513 | I23: =IF(H23="","",IF(MONTH(H23+1)<>MONTH(H23),"",H23+1)) -> 46514 | J23: =IF(I23="","",IF(MONTH(I23+1)<>MONTH(I23),"",I23+1)) -> 46515 | K23: =IF(J23="","",IF(MONTH(J23+1)<>MONTH(J23),"",J23+1)) -> 46516 | L23: 14 | M23: =IF(S22="","",IF(MONTH(S22+1)<>MONTH(S22),"",S22+1)) -> 46545 | N23: =IF(M23="","",IF(MONTH(M23+1)<>MONTH(M23),"",M23+1)) -> 46546 | O23: =IF(N23="","",IF(MONTH(N23+1)<>MONTH(N23),"",N23+1)) -> 46547 | P23: =IF(O23="","",IF(MONTH(O23+1)<>MONTH(O23),"",O23+1)) -> 46548 | Q23: =IF(P23="","",IF(MONTH(P23+1)<>MONTH(P23),"",P23+1)) -> 46549 | R23: =IF(Q23="","",IF(MONTH(Q23+1)<>MONTH(Q23),"",Q23+1)) -> 46550 | S23: =IF(R23="","",IF(MONTH(R23+1)<>MONTH(R23),"",R23+1)) -> 46551 | T23: 18 | U23: =IF(AA22="","",IF(MONTH(AA22+1)<>MONTH(AA22),"",AA22+1)) -> 46573 | V23: =IF(U23="","",IF(MONTH(U23+1)<>MONTH(U23),"",U23+1)) -> 46574 | W23: =IF(V23="","",IF(MONTH(V23+1)<>MONTH(V23),"",V23+1)) -> 46575 | X23: =IF(W23="","",IF(MONTH(W23+1)<>MONTH(W23),"",W23+1)) -> 46576 | Y23: =IF(X23="","",IF(MONTH(X23+1)<>MONTH(X23),"",X23+1)) -> 46577 | Z23: =IF(Y23="","",IF(MONTH(Y23+1)<>MONTH(Y23),"",Y23+1)) -> 46578 | AA23: =IF(Z23="","",IF(MONTH(Z23+1)<>MONTH(Z23),"",Z23+1)) -> 46579 | AC23: =IF(AI22="","",IF(MONTH(AI22+1)<>MONTH(AI22),"",AI22+1)) -> 46601 | AD23: =IF(AC23="","",IF(MONTH(AC23+1)<>MONTH(AC23),"",AC23+1)) -> 46602 | AE23: =IF(AD23="","",IF(MONTH(AD23+1)<>MONTH(AD23),"",AD23+1)) -> 46603 | AF23: =IF(AE23="","",IF(MONTH(AE23+1)<>MONTH(AE23),"",AE23+1)) -> 46604 | AG23: =IF(AF23="","",IF(MONTH(AF23+1)<>MONTH(AF23),"",AF23+1)) -> 46605 | AH23: =IF(AG23="","",IF(MONTH(AG23+1)<>MONTH(AG23),"",AG23+1)) -> 46606 | AI23: =IF(AH23="","",IF(MONTH(AH23+1)<>MONTH(AH23),"",AH23+1)) -> 46607
D24: 10 | E24: =IF(K23="","",IF(MONTH(K23+1)<>MONTH(K23),"",K23+1)) -> 46517 | F24: =IF(E24="","",IF(MONTH(E24+1)<>MONTH(E24),"",E24+1)) -> 46518 | G24: =IF(F24="","",IF(MONTH(F24+1)<>MONTH(F24),"",F24+1)) -> 46519 | H24: =IF(G24="","",IF(MONTH(G24+1)<>MONTH(G24),"",G24+1)) -> 46520 | I24: =IF(H24="","",IF(MONTH(H24+1)<>MONTH(H24),"",H24+1)) -> 46521 | J24: =IF(I24="","",IF(MONTH(I24+1)<>MONTH(I24),"",I24+1)) -> 46522 | K24: =IF(J24="","",IF(MONTH(J24+1)<>MONTH(J24),"",J24+1)) -> 46523 | L24: 15 | M24: =IF(S23="","",IF(MONTH(S23+1)<>MONTH(S23),"",S23+1)) -> 46552 | N24: =IF(M24="","",IF(MONTH(M24+1)<>MONTH(M24),"",M24+1)) -> 46553 | O24: =IF(N24="","",IF(MONTH(N24+1)<>MONTH(N24),"",N24+1)) -> 46554 | P24: =IF(O24="","",IF(MONTH(O24+1)<>MONTH(O24),"",O24+1)) -> 46555 | Q24: =IF(P24="","",IF(MONTH(P24+1)<>MONTH(P24),"",P24+1)) -> 46556 | R24: =IF(Q24="","",IF(MONTH(Q24+1)<>MONTH(Q24),"",Q24+1)) -> 46557 | S24: =IF(R24="","",IF(MONTH(R24+1)<>MONTH(R24),"",R24+1)) -> 46558 | T24: 19 | U24: =IF(AA23="","",IF(MONTH(AA23+1)<>MONTH(AA23),"",AA23+1)) -> 46580 | V24: =IF(U24="","",IF(MONTH(U24+1)<>MONTH(U24),"",U24+1)) -> 46581 | W24: =IF(V24="","",IF(MONTH(V24+1)<>MONTH(V24),"",V24+1)) -> 46582 | X24: =IF(W24="","",IF(MONTH(W24+1)<>MONTH(W24),"",W24+1)) -> 46583 | Y24: =IF(X24="","",IF(MONTH(X24+1)<>MONTH(X24),"",X24+1)) -> 46584 | Z24: =IF(Y24="","",IF(MONTH(Y24+1)<>MONTH(Y24),"",Y24+1)) -> 46585 | AA24: =IF(Z24="","",IF(MONTH(Z24+1)<>MONTH(Z24),"",Z24+1)) -> 46586 | AB24: 1 | AC24: =IF(AI23="","",IF(MONTH(AI23+1)<>MONTH(AI23),"",AI23+1)) -> 46608 | AD24: =IF(AC24="","",IF(MONTH(AC24+1)<>MONTH(AC24),"",AC24+1)) -> 46609 | AE24: =IF(AD24="","",IF(MONTH(AD24+1)<>MONTH(AD24),"",AD24+1)) -> 46610 | AF24: =IF(AE24="","",IF(MONTH(AE24+1)<>MONTH(AE24),"",AE24+1)) -> 46611 | AG24: =IF(AF24="","",IF(MONTH(AF24+1)<>MONTH(AF24),"",AF24+1)) -> 46612 | AH24: =IF(AG24="","",IF(MONTH(AG24+1)<>MONTH(AG24),"",AG24+1)) -> 46613 | AI24: =IF(AH24="","",IF(MONTH(AH24+1)<>MONTH(AH24),"",AH24+1)) -> 46614
D25: 11 | E25: =IF(K24="","",IF(MONTH(K24+1)<>MONTH(K24),"",K24+1)) -> 46524 | F25: =IF(E25="","",IF(MONTH(E25+1)<>MONTH(E25),"",E25+1)) -> 46525 | G25: =IF(F25="","",IF(MONTH(F25+1)<>MONTH(F25),"",F25+1)) -> 46526 | H25: =IF(G25="","",IF(MONTH(G25+1)<>MONTH(G25),"",G25+1)) -> 46527 | I25: =IF(H25="","",IF(MONTH(H25+1)<>MONTH(H25),"",H25+1)) -> 46528 | J25: =IF(I25="","",IF(MONTH(I25+1)<>MONTH(I25),"",I25+1)) -> 46529 | K25: =IF(J25="","",IF(MONTH(J25+1)<>MONTH(J25),"",J25+1)) -> 46530 | L25: 16 | M25: =IF(S24="","",IF(MONTH(S24+1)<>MONTH(S24),"",S24+1)) -> 46559 | N25: =IF(M25="","",IF(MONTH(M25+1)<>MONTH(M25),"",M25+1)) -> 46560 | O25: =IF(N25="","",IF(MONTH(N25+1)<>MONTH(N25),"",N25+1)) -> 46561 | P25: =IF(O25="","",IF(MONTH(O25+1)<>MONTH(O25),"",O25+1)) -> 46562 | Q25: =IF(P25="","",IF(MONTH(P25+1)<>MONTH(P25),"",P25+1)) -> 46563 | R25: =IF(Q25="","",IF(MONTH(Q25+1)<>MONTH(Q25),"",Q25+1)) -> 46564 | S25: =IF(R25="","",IF(MONTH(R25+1)<>MONTH(R25),"",R25+1)) -> 46565 | T25: 20 | U25: =IF(AA24="","",IF(MONTH(AA24+1)<>MONTH(AA24),"",AA24+1)) -> 46587 | V25: =IF(U25="","",IF(MONTH(U25+1)<>MONTH(U25),"",U25+1)) -> 46588 | W25: =IF(V25="","",IF(MONTH(V25+1)<>MONTH(V25),"",V25+1)) -> 46589 | X25: =IF(W25="","",IF(MONTH(W25+1)<>MONTH(W25),"",W25+1)) -> 46590 | Y25: =IF(X25="","",IF(MONTH(X25+1)<>MONTH(X25),"",X25+1)) -> 46591 | Z25: =IF(Y25="","",IF(MONTH(Y25+1)<>MONTH(Y25),"",Y25+1)) -> 46592 | AA25: =IF(Z25="","",IF(MONTH(Z25+1)<>MONTH(Z25),"",Z25+1)) -> 46593 | AB25: 2 | AC25: =IF(AI24="","",IF(MONTH(AI24+1)<>MONTH(AI24),"",AI24+1)) -> 46615 | AD25: =IF(AC25="","",IF(MONTH(AC25+1)<>MONTH(AC25),"",AC25+1)) -> 46616 | AE25: =IF(AD25="","",IF(MONTH(AD25+1)<>MONTH(AD25),"",AD25+1)) -> 46617 | AF25: =IF(AE25="","",IF(MONTH(AE25+1)<>MONTH(AE25),"",AE25+1)) -> 46618 | AG25: =IF(AF25="","",IF(MONTH(AF25+1)<>MONTH(AF25),"",AF25+1)) -> 46619 | AH25: =IF(AG25="","",IF(MONTH(AG25+1)<>MONTH(AG25),"",AG25+1)) -> 46620 | AI25: =IF(AH25="","",IF(MONTH(AH25+1)<>MONTH(AH25),"",AH25+1)) -> 46621
D26: 12 | E26: =IF(K25="","",IF(MONTH(K25+1)<>MONTH(K25),"",K25+1)) -> 46531 | F26: =IF(E26="","",IF(MONTH(E26+1)<>MONTH(E26),"",E26+1)) -> 46532 | G26: =IF(F26="","",IF(MONTH(F26+1)<>MONTH(F26),"",F26+1)) -> 46533 | H26: =IF(G26="","",IF(MONTH(G26+1)<>MONTH(G26),"",G26+1)) -> 46534 | I26: =IF(H26="","",IF(MONTH(H26+1)<>MONTH(H26),"",H26+1)) -> 46535 | J26: =IF(I26="","",IF(MONTH(I26+1)<>MONTH(I26),"",I26+1)) -> 46536 | K26: =IF(J26="","",IF(MONTH(J26+1)<>MONTH(J26),"",J26+1)) -> 46537 | L26: 17 | M26: =IF(S25="","",IF(MONTH(S25+1)<>MONTH(S25),"",S25+1)) -> 46566 | N26: =IF(M26="","",IF(MONTH(M26+1)<>MONTH(M26),"",M26+1)) -> 46567 | O26: =IF(N26="","",IF(MONTH(N26+1)<>MONTH(N26),"",N26+1)) -> 46568 | P26: =IF(O26="","",IF(MONTH(O26+1)<>MONTH(O26),"",O26+1)) | Q26: =IF(P26="","",IF(MONTH(P26+1)<>MONTH(P26),"",P26+1)) | R26: =IF(Q26="","",IF(MONTH(Q26+1)<>MONTH(Q26),"",Q26+1)) | S26: =IF(R26="","",IF(MONTH(R26+1)<>MONTH(R26),"",R26+1)) | U26: =IF(AA25="","",IF(MONTH(AA25+1)<>MONTH(AA25),"",AA25+1)) -> 46594 | V26: =IF(U26="","",IF(MONTH(U26+1)<>MONTH(U26),"",U26+1)) -> 46595 | W26: =IF(V26="","",IF(MONTH(V26+1)<>MONTH(V26),"",V26+1)) -> 46596 | X26: =IF(W26="","",IF(MONTH(W26+1)<>MONTH(W26),"",W26+1)) -> 46597 | Y26: =IF(X26="","",IF(MONTH(X26+1)<>MONTH(X26),"",X26+1)) -> 46598 | Z26: =IF(Y26="","",IF(MONTH(Y26+1)<>MONTH(Y26),"",Y26+1)) -> 46599 | AA26: =IF(Z26="","",IF(MONTH(Z26+1)<>MONTH(Z26),"",Z26+1)) | AB26: 3 | AC26: =IF(AI25="","",IF(MONTH(AI25+1)<>MONTH(AI25),"",AI25+1)) -> 46622 | AD26: =IF(AC26="","",IF(MONTH(AC26+1)<>MONTH(AC26),"",AC26+1)) -> 46623 | AE26: =IF(AD26="","",IF(MONTH(AD26+1)<>MONTH(AD26),"",AD26+1)) -> 46624 | AF26: =IF(AE26="","",IF(MONTH(AE26+1)<>MONTH(AE26),"",AE26+1)) -> 46625 | AG26: =IF(AF26="","",IF(MONTH(AF26+1)<>MONTH(AF26),"",AF26+1)) -> 46626 | AH26: =IF(AG26="","",IF(MONTH(AG26+1)<>MONTH(AG26),"",AG26+1)) -> 46627 | AI26: =IF(AH26="","",IF(MONTH(AH26+1)<>MONTH(AH26),"",AH26+1)) -> 46628
D27: 13 | E27: =IF(K26="","",IF(MONTH(K26+1)<>MONTH(K26),"",K26+1)) -> 46538 | F27: =IF(E27="","",IF(MONTH(E27+1)<>MONTH(E27),"",E27+1)) | G27: =IF(F27="","",IF(MONTH(F27+1)<>MONTH(F27),"",F27+1)) | H27: =IF(G27="","",IF(MONTH(G27+1)<>MONTH(G27),"",G27+1)) | I27: =IF(H27="","",IF(MONTH(H27+1)<>MONTH(H27),"",H27+1)) | J27: =IF(I27="","",IF(MONTH(I27+1)<>MONTH(I27),"",I27+1)) | K27: =IF(J27="","",IF(MONTH(J27+1)<>MONTH(J27),"",J27+1)) | M27: =IF(S26="","",IF(MONTH(S26+1)<>MONTH(S26),"",S26+1)) | N27: =IF(M27="","",IF(MONTH(M27+1)<>MONTH(M27),"",M27+1)) | O27: =IF(N27="","",IF(MONTH(N27+1)<>MONTH(N27),"",N27+1)) | P27: =IF(O27="","",IF(MONTH(O27+1)<>MONTH(O27),"",O27+1)) | Q27: =IF(P27="","",IF(MONTH(P27+1)<>MONTH(P27),"",P27+1)) | R27: =IF(Q27="","",IF(MONTH(Q27+1)<>MONTH(Q27),"",Q27+1)) | S27: =IF(R27="","",IF(MONTH(R27+1)<>MONTH(R27),"",R27+1)) | U27: =IF(AA26="","",IF(MONTH(AA26+1)<>MONTH(AA26),"",AA26+1)) | V27: =IF(U27="","",IF(MONTH(U27+1)<>MONTH(U27),"",U27+1)) | W27: =IF(V27="","",IF(MONTH(V27+1)<>MONTH(V27),"",V27+1)) | X27: =IF(W27="","",IF(MONTH(W27+1)<>MONTH(W27),"",W27+1)) | Y27: =IF(X27="","",IF(MONTH(X27+1)<>MONTH(X27),"",X27+1)) | Z27: =IF(Y27="","",IF(MONTH(Y27+1)<>MONTH(Y27),"",Y27+1)) | AA27: =IF(Z27="","",IF(MONTH(Z27+1)<>MONTH(Z27),"",Z27+1)) | AB27: 4 | AC27: =IF(AI26="","",IF(MONTH(AI26+1)<>MONTH(AI26),"",AI26+1)) -> 46629 | AD27: =IF(AC27="","",IF(MONTH(AC27+1)<>MONTH(AC27),"",AC27+1)) -> 46630 | AE27: =IF(AD27="","",IF(MONTH(AD27+1)<>MONTH(AD27),"",AD27+1)) | AF27: =IF(AE27="","",IF(MONTH(AE27+1)<>MONTH(AE27),"",AE27+1)) | AG27: =IF(AF27="","",IF(MONTH(AF27+1)<>MONTH(AF27),"",AF27+1)) | AH27: =IF(AG27="","",IF(MONTH(AG27+1)<>MONTH(AG27),"",AG27+1)) | AI27: =IF(AH27="","",IF(MONTH(AH27+1)<>MONTH(AH27),"",AH27+1))
D29: Semana | E29: =DATE(YEAR(AC20+42),MONTH(AC20+42),1) -> 46631 | L29: Semana | M29: =DATE(YEAR(E29+42),MONTH(E29+42),1) -> 46661 | T29: Semana | U29: =DATE(YEAR(M29+42),MONTH(M29+42),1) -> 46692 | AB29: Semana | AC29: =DATE(YEAR(U29+42),MONTH(U29+42),1) -> 46722
E30: =CHOOSE(1+MOD($T$2+1-2,7),"D","L","M","M","J","V","S") -> L | F30: =CHOOSE(1+MOD($T$2+2-2,7),"D","L","M","M","J","V","S") -> M | G30: =CHOOSE(1+MOD($T$2+3-2,7),"D","L","M","M","J","V","S") -> M | H30: =CHOOSE(1+MOD($T$2+4-2,7),"D","L","M","M","J","V","S") -> J | I30: =CHOOSE(1+MOD($T$2+5-2,7),"D","L","M","M","J","V","S") -> V | J30: =CHOOSE(1+MOD($T$2+6-2,7),"D","L","M","M","J","V","S") -> S | K30: =CHOOSE(1+MOD($T$2+7-2,7),"D","L","M","M","J","V","S") -> D | M30: =CHOOSE(1+MOD($T$2+1-2,7),"D","L","M","M","J","V","S") -> L | N30: =CHOOSE(1+MOD($T$2+2-2,7),"D","L","M","M","J","V","S") -> M | O30: =CHOOSE(1+MOD($T$2+3-2,7),"D","L","M","M","J","V","S") -> M | P30: =CHOOSE(1+MOD($T$2+4-2,7),"D","L","M","M","J","V","S") -> J | Q30: =CHOOSE(1+MOD($T$2+5-2,7),"D","L","M","M","J","V","S") -> V | R30: =CHOOSE(1+MOD($T$2+6-2,7),"D","L","M","M","J","V","S") -> S | S30: =CHOOSE(1+MOD($T$2+7-2,7),"D","L","M","M","J","V","S") -> D | U30: =CHOOSE(1+MOD($T$2+1-2,7),"D","L","M","M","J","V","S") -> L | V30: =CHOOSE(1+MOD($T$2+2-2,7),"D","L","M","M","J","V","S") -> M | W30: =CHOOSE(1+MOD($T$2+3-2,7),"D","L","M","M","J","V","S") -> M | X30: =CHOOSE(1+MOD($T$2+4-2,7),"D","L","M","M","J","V","S") -> J | Y30: =CHOOSE(1+MOD($T$2+5-2,7),"D","L","M","M","J","V","S") -> V | Z30: =CHOOSE(1+MOD($T$2+6-2,7),"D","L","M","M","J","V","S") -> S | AA30: =CHOOSE(1+MOD($T$2+7-2,7),"D","L","M","M","J","V","S") -> D | AC30: =CHOOSE(1+MOD($T$2+1-2,7),"D","L","M","M","J","V","S") -> L | AD30: =CHOOSE(1+MOD($T$2+2-2,7),"D","L","M","M","J","V","S") -> M | AE30: =CHOOSE(1+MOD($T$2+3-2,7),"D","L","M","M","J","V","S") -> M | AF30: =CHOOSE(1+MOD($T$2+4-2,7),"D","L","M","M","J","V","S") -> J | AG30: =CHOOSE(1+MOD($T$2+5-2,7),"D","L","M","M","J","V","S") -> V | AH30: =CHOOSE(1+MOD($T$2+6-2,7),"D","L","M","M","J","V","S") -> S | AI30: =CHOOSE(1+MOD($T$2+7-2,7),"D","L","M","M","J","V","S") -> D
D31: 4 | E31: =IF(WEEKDAY(E29,1)=MOD($T$2-1,7)+1,E29,"") | F31: =IF(E31="",IF(WEEKDAY(E29,1)=MOD($T$2,7)+1,E29,""),E31+1) | G31: =IF(F31="",IF(WEEKDAY(E29,1)=MOD($T$2+1,7)+1,E29,""),F31+1) -> 46631 | H31: =IF(G31="",IF(WEEKDAY(E29,1)=MOD($T$2+2,7)+1,E29,""),G31+1) -> 46632 | I31: =IF(H31="",IF(WEEKDAY(E29,1)=MOD($T$2+3,7)+1,E29,""),H31+1) -> 46633 | J31: =IF(I31="",IF(WEEKDAY(E29,1)=MOD($T$2+4,7)+1,E29,""),I31+1) -> 46634 | K31: =IF(J31="",IF(WEEKDAY(E29,1)=MOD($T$2+5,7)+1,E29,""),J31+1) -> 46635 | L31: 8 | M31: =IF(WEEKDAY(M29,1)=MOD($T$2-1,7)+1,M29,"") | N31: =IF(M31="",IF(WEEKDAY(M29,1)=MOD($T$2,7)+1,M29,""),M31+1) | O31: =IF(N31="",IF(WEEKDAY(M29,1)=MOD($T$2+1,7)+1,M29,""),N31+1) | P31: =IF(O31="",IF(WEEKDAY(N29,1)=MOD($T$2+1,7)+1,N29,""),O31+1) | Q31: =IF(P31="",IF(WEEKDAY(M29,1)=MOD($T$2+3,7)+1,M29,""),P31+1) -> 46661 | R31: =IF(Q31="",IF(WEEKDAY(M29,1)=MOD($T$2+4,7)+1,M29,""),Q31+1) -> 46662 | S31: =IF(R31="",IF(WEEKDAY(M29,1)=MOD($T$2+5,7)+1,M29,""),R31+1) -> 46663 | T31: 13 | U31: =IF(WEEKDAY(U29,1)=MOD($T$2-1,7)+1,U29,"") -> 46692 | V31: =IF(U31="",IF(WEEKDAY(U29,1)=MOD($T$2,7)+1,U29,""),U31+1) -> 46693 | W31: =IF(V31="",IF(WEEKDAY(U29,1)=MOD($T$2+1,7)+1,U29,""),V31+1) -> 46694 | X31: =IF(W31="",IF(WEEKDAY(U29,1)=MOD($T$2+2,7)+1,U29,""),W31+1) -> 46695 | Y31: =IF(X31="",IF(WEEKDAY(U29,1)=MOD($T$2+3,7)+1,U29,""),X31+1) -> 46696 | Z31: =IF(Y31="",IF(WEEKDAY(U29,1)=MOD($T$2+4,7)+1,U29,""),Y31+1) -> 46697 | AA31: =IF(Z31="",IF(WEEKDAY(U29,1)=MOD($T$2+5,7)+1,U29,""),Z31+1) -> 46698 | AB31: 17 | AC31: =IF(WEEKDAY(AC29,1)=MOD($T$2-1,7)+1,AC29,"") | AD31: =IF(AC31="",IF(WEEKDAY(AC29,1)=MOD($T$2,7)+1,AC29,""),AC31+1) | AE31: =IF(AD31="",IF(WEEKDAY(AC29,1)=MOD($T$2+1,7)+1,AC29,""),AD31+1) -> 46722 | AF31: =IF(AE31="",IF(WEEKDAY(AC29,1)=MOD($T$2+2,7)+1,AC29,""),AE31+1) -> 46723 | AG31: =IF(AF31="",IF(WEEKDAY(AC29,1)=MOD($T$2+3,7)+1,AC29,""),AF31+1) -> 46724 | AH31: =IF(AG31="",IF(WEEKDAY(AC29,1)=MOD($T$2+4,7)+1,AC29,""),AG31+1) -> 46725 | AI31: =IF(AH31="",IF(WEEKDAY(AC29,1)=MOD($T$2+5,7)+1,AC29,""),AH31+1) -> 46726
D32: 5 | E32: =IF(K31="","",IF(MONTH(K31+1)<>MONTH(K31),"",K31+1)) -> 46636 | F32: =IF(E32="","",IF(MONTH(E32+1)<>MONTH(E32),"",E32+1)) -> 46637 | G32: =IF(F32="","",IF(MONTH(F32+1)<>MONTH(F32),"",F32+1)) -> 46638 | H32: =IF(G32="","",IF(MONTH(G32+1)<>MONTH(G32),"",G32+1)) -> 46639 | I32: =IF(H32="","",IF(MONTH(H32+1)<>MONTH(H32),"",H32+1)) -> 46640 | J32: =IF(I32="","",IF(MONTH(I32+1)<>MONTH(I32),"",I32+1)) -> 46641 | K32: =IF(J32="","",IF(MONTH(J32+1)<>MONTH(J32),"",J32+1)) -> 46642 | L32: 9 | M32: =IF(S31="","",IF(MONTH(S31+1)<>MONTH(S31),"",S31+1)) -> 46664 | N32: =IF(M32="","",IF(MONTH(M32+1)<>MONTH(M32),"",M32+1)) -> 46665 | O32: =IF(N32="","",IF(MONTH(N32+1)<>MONTH(N32),"",N32+1)) -> 46666 | P32: =IF(O32="","",IF(MONTH(O32+1)<>MONTH(O32),"",O32+1)) -> 46667 | Q32: =IF(P32="","",IF(MONTH(P32+1)<>MONTH(P32),"",P32+1)) -> 46668 | R32: =IF(Q32="","",IF(MONTH(Q32+1)<>MONTH(Q32),"",Q32+1)) -> 46669 | S32: =IF(R32="","",IF(MONTH(R32+1)<>MONTH(R32),"",R32+1)) -> 46670 | T32: 14 | U32: =IF(AA31="","",IF(MONTH(AA31+1)<>MONTH(AA31),"",AA31+1)) -> 46699 | V32: =IF(U32="","",IF(MONTH(U32+1)<>MONTH(U32),"",U32+1)) -> 46700 | W32: =IF(V32="","",IF(MONTH(V32+1)<>MONTH(V32),"",V32+1)) -> 46701 | X32: =IF(W32="","",IF(MONTH(W32+1)<>MONTH(W32),"",W32+1)) -> 46702 | Y32: =IF(X32="","",IF(MONTH(X32+1)<>MONTH(X32),"",X32+1)) -> 46703 | Z32: =IF(Y32="","",IF(MONTH(Y32+1)<>MONTH(Y32),"",Y32+1)) -> 46704 | AA32: =IF(Z32="","",IF(MONTH(Z32+1)<>MONTH(Z32),"",Z32+1)) -> 46705 | AB32: 18 | AC32: =IF(AI31="","",IF(MONTH(AI31+1)<>MONTH(AI31),"",AI31+1)) -> 46727 | AD32: =IF(AC32="","",IF(MONTH(AC32+1)<>MONTH(AC32),"",AC32+1)) -> 46728 | AE32: =IF(AD32="","",IF(MONTH(AD32+1)<>MONTH(AD32),"",AD32+1)) -> 46729 | AF32: =IF(AE32="","",IF(MONTH(AE32+1)<>MONTH(AE32),"",AE32+1)) -> 46730 | AG32: =IF(AF32="","",IF(MONTH(AF32+1)<>MONTH(AF32),"",AF32+1)) -> 46731 | AH32: =IF(AG32="","",IF(MONTH(AG32+1)<>MONTH(AG32),"",AG32+1)) -> 46732 | AI32: =IF(AH32="","",IF(MONTH(AH32+1)<>MONTH(AH32),"",AH32+1)) -> 46733
D33: 6 | E33: =IF(K32="","",IF(MONTH(K32+1)<>MONTH(K32),"",K32+1)) -> 46643 | F33: =IF(E33="","",IF(MONTH(E33+1)<>MONTH(E33),"",E33+1)) -> 46644 | G33: =IF(F33="","",IF(MONTH(F33+1)<>MONTH(F33),"",F33+1)) -> 46645 | H33: =IF(G33="","",IF(MONTH(G33+1)<>MONTH(G33),"",G33+1)) -> 46646 | I33: =IF(H33="","",IF(MONTH(H33+1)<>MONTH(H33),"",H33+1)) -> 46647 | J33: =IF(I33="","",IF(MONTH(I33+1)<>MONTH(I33),"",I33+1)) -> 46648 | K33: =IF(J33="","",IF(MONTH(J33+1)<>MONTH(J33),"",J33+1)) -> 46649 | L33: 10 | M33: =IF(S32="","",IF(MONTH(S32+1)<>MONTH(S32),"",S32+1)) -> 46671 | N33: =IF(M33="","",IF(MONTH(M33+1)<>MONTH(M33),"",M33+1)) -> 46672 | O33: =IF(N33="","",IF(MONTH(N33+1)<>MONTH(N33),"",N33+1)) -> 46673 | P33: =IF(O33="","",IF(MONTH(O33+1)<>MONTH(O33),"",O33+1)) -> 46674 | Q33: =IF(P33="","",IF(MONTH(P33+1)<>MONTH(P33),"",P33+1)) -> 46675 | R33: =IF(Q33="","",IF(MONTH(Q33+1)<>MONTH(Q33),"",Q33+1)) -> 46676 | S33: =IF(R33="","",IF(MONTH(R33+1)<>MONTH(R33),"",R33+1)) -> 46677 | T33: 15 | U33: =IF(AA32="","",IF(MONTH(AA32+1)<>MONTH(AA32),"",AA32+1)) -> 46706 | V33: =IF(U33="","",IF(MONTH(U33+1)<>MONTH(U33),"",U33+1)) -> 46707 | W33: =IF(V33="","",IF(MONTH(V33+1)<>MONTH(V33),"",V33+1)) -> 46708 | X33: =IF(W33="","",IF(MONTH(W33+1)<>MONTH(W33),"",W33+1)) -> 46709 | Y33: =IF(X33="","",IF(MONTH(X33+1)<>MONTH(X33),"",X33+1)) -> 46710 | Z33: =IF(Y33="","",IF(MONTH(Y33+1)<>MONTH(Y33),"",Y33+1)) -> 46711 | AA33: =IF(Z33="","",IF(MONTH(Z33+1)<>MONTH(Z33),"",Z33+1)) -> 46712 | AB33: 19 | AC33: =IF(AI32="","",IF(MONTH(AI32+1)<>MONTH(AI32),"",AI32+1)) -> 46734 | AD33: =IF(AC33="","",IF(MONTH(AC33+1)<>MONTH(AC33),"",AC33+1)) -> 46735 | AE33: =IF(AD33="","",IF(MONTH(AD33+1)<>MONTH(AD33),"",AD33+1)) -> 46736 | AF33: =IF(AE33="","",IF(MONTH(AE33+1)<>MONTH(AE33),"",AE33+1)) -> 46737 | AG33: =IF(AF33="","",IF(MONTH(AF33+1)<>MONTH(AF33),"",AF33+1)) -> 46738 | AH33: =IF(AG33="","",IF(MONTH(AG33+1)<>MONTH(AG33),"",AG33+1)) -> 46739 | AI33: =IF(AH33="","",IF(MONTH(AH33+1)<>MONTH(AH33),"",AH33+1)) -> 46740
D34: 7 | E34: =IF(K33="","",IF(MONTH(K33+1)<>MONTH(K33),"",K33+1)) -> 46650 | F34: =IF(E34="","",IF(MONTH(E34+1)<>MONTH(E34),"",E34+1)) -> 46651 | G34: =IF(F34="","",IF(MONTH(F34+1)<>MONTH(F34),"",F34+1)) -> 46652 | H34: =IF(G34="","",IF(MONTH(G34+1)<>MONTH(G34),"",G34+1)) -> 46653 | I34: =IF(H34="","",IF(MONTH(H34+1)<>MONTH(H34),"",H34+1)) -> 46654 | J34: =IF(I34="","",IF(MONTH(I34+1)<>MONTH(I34),"",I34+1)) -> 46655 | K34: =IF(J34="","",IF(MONTH(J34+1)<>MONTH(J34),"",J34+1)) -> 46656 | L34: 11 | M34: =IF(S33="","",IF(MONTH(S33+1)<>MONTH(S33),"",S33+1)) -> 46678 | N34: =IF(M34="","",IF(MONTH(M34+1)<>MONTH(M34),"",M34+1)) -> 46679 | O34: =IF(N34="","",IF(MONTH(N34+1)<>MONTH(N34),"",N34+1)) -> 46680 | P34: =IF(O34="","",IF(MONTH(O34+1)<>MONTH(O34),"",O34+1)) -> 46681 | Q34: =IF(P34="","",IF(MONTH(P34+1)<>MONTH(P34),"",P34+1)) -> 46682 | R34: =IF(Q34="","",IF(MONTH(Q34+1)<>MONTH(Q34),"",Q34+1)) -> 46683 | S34: =IF(R34="","",IF(MONTH(R34+1)<>MONTH(R34),"",R34+1)) -> 46684 | T34: 16 | U34: =IF(AA33="","",IF(MONTH(AA33+1)<>MONTH(AA33),"",AA33+1)) -> 46713 | V34: =IF(U34="","",IF(MONTH(U34+1)<>MONTH(U34),"",U34+1)) -> 46714 | W34: =IF(V34="","",IF(MONTH(V34+1)<>MONTH(V34),"",V34+1)) -> 46715 | X34: =IF(W34="","",IF(MONTH(W34+1)<>MONTH(W34),"",W34+1)) -> 46716 | Y34: =IF(X34="","",IF(MONTH(X34+1)<>MONTH(X34),"",X34+1)) -> 46717 | Z34: =IF(Y34="","",IF(MONTH(Y34+1)<>MONTH(Y34),"",Y34+1)) -> 46718 | AA34: =IF(Z34="","",IF(MONTH(Z34+1)<>MONTH(Z34),"",Z34+1)) -> 46719 | AB34: 20 | AC34: =IF(AI33="","",IF(MONTH(AI33+1)<>MONTH(AI33),"",AI33+1)) -> 46741 | AD34: =IF(AC34="","",IF(MONTH(AC34+1)<>MONTH(AC34),"",AC34+1)) -> 46742 | AE34: =IF(AD34="","",IF(MONTH(AD34+1)<>MONTH(AD34),"",AD34+1)) -> 46743 | AF34: =IF(AE34="","",IF(MONTH(AE34+1)<>MONTH(AE34),"",AE34+1)) -> 46744 | AG34: =IF(AF34="","",IF(MONTH(AF34+1)<>MONTH(AF34),"",AF34+1)) -> 46745 | AH34: =IF(AG34="","",IF(MONTH(AG34+1)<>MONTH(AG34),"",AG34+1)) -> 46746 | AI34: =IF(AH34="","",IF(MONTH(AH34+1)<>MONTH(AH34),"",AH34+1)) -> 46747
D35: 8 | E35: =IF(K34="","",IF(MONTH(K34+1)<>MONTH(K34),"",K34+1)) -> 46657 | F35: =IF(E35="","",IF(MONTH(E35+1)<>MONTH(E35),"",E35+1)) -> 46658 | G35: =IF(F35="","",IF(MONTH(F35+1)<>MONTH(F35),"",F35+1)) -> 46659 | H35: =IF(G35="","",IF(MONTH(G35+1)<>MONTH(G35),"",G35+1)) -> 46660 | I35: =IF(H35="","",IF(MONTH(H35+1)<>MONTH(H35),"",H35+1)) | J35: =IF(I35="","",IF(MONTH(I35+1)<>MONTH(I35),"",I35+1)) | K35: =IF(J35="","",IF(MONTH(J35+1)<>MONTH(J35),"",J35+1)) | L35: 12 | M35: =IF(S34="","",IF(MONTH(S34+1)<>MONTH(S34),"",S34+1)) -> 46685 | N35: =IF(M35="","",IF(MONTH(M35+1)<>MONTH(M35),"",M35+1)) -> 46686 | O35: =IF(N35="","",IF(MONTH(N35+1)<>MONTH(N35),"",N35+1)) -> 46687 | P35: =IF(O35="","",IF(MONTH(O35+1)<>MONTH(O35),"",O35+1)) -> 46688 | Q35: =IF(P35="","",IF(MONTH(P35+1)<>MONTH(P35),"",P35+1)) -> 46689 | R35: =IF(Q35="","",IF(MONTH(Q35+1)<>MONTH(Q35),"",Q35+1)) -> 46690 | S35: =IF(R35="","",IF(MONTH(R35+1)<>MONTH(R35),"",R35+1)) -> 46691 | T35: 17 | U35: =IF(AA34="","",IF(MONTH(AA34+1)<>MONTH(AA34),"",AA34+1)) -> 46720 | V35: =IF(U35="","",IF(MONTH(U35+1)<>MONTH(U35),"",U35+1)) -> 46721 | W35: =IF(V35="","",IF(MONTH(V35+1)<>MONTH(V35),"",V35+1)) | X35: =IF(W35="","",IF(MONTH(W35+1)<>MONTH(W35),"",W35+1)) | Y35: =IF(X35="","",IF(MONTH(X35+1)<>MONTH(X35),"",X35+1)) | Z35: =IF(Y35="","",IF(MONTH(Y35+1)<>MONTH(Y35),"",Y35+1)) | AA35: =IF(Z35="","",IF(MONTH(Z35+1)<>MONTH(Z35),"",Z35+1)) | AC35: =IF(AI34="","",IF(MONTH(AI34+1)<>MONTH(AI34),"",AI34+1)) -> 46748 | AD35: =IF(AC35="","",IF(MONTH(AC35+1)<>MONTH(AC35),"",AC35+1)) -> 46749 | AE35: =IF(AD35="","",IF(MONTH(AD35+1)<>MONTH(AD35),"",AD35+1)) -> 46750 | AF35: =IF(AE35="","",IF(MONTH(AE35+1)<>MONTH(AE35),"",AE35+1)) -> 46751 | AG35: =IF(AF35="","",IF(MONTH(AF35+1)<>MONTH(AF35),"",AF35+1)) -> 46752 | AH35: =IF(AG35="","",IF(MONTH(AG35+1)<>MONTH(AG35),"",AG35+1)) | AI35: =IF(AH35="","",IF(MONTH(AH35+1)<>MONTH(AH35),"",AH35+1))
E36: =IF(K35="","",IF(MONTH(K35+1)<>MONTH(K35),"",K35+1)) | F36: =IF(E36="","",IF(MONTH(E36+1)<>MONTH(E36),"",E36+1)) | G36: =IF(F36="","",IF(MONTH(F36+1)<>MONTH(F36),"",F36+1)) | H36: =IF(G36="","",IF(MONTH(G36+1)<>MONTH(G36),"",G36+1)) | I36: =IF(H36="","",IF(MONTH(H36+1)<>MONTH(H36),"",H36+1)) | J36: =IF(I36="","",IF(MONTH(I36+1)<>MONTH(I36),"",I36+1)) | K36: =IF(J36="","",IF(MONTH(J36+1)<>MONTH(J36),"",J36+1)) | M36: =IF(S35="","",IF(MONTH(S35+1)<>MONTH(S35),"",S35+1)) | N36: =IF(M36="","",IF(MONTH(M36+1)<>MONTH(M36),"",M36+1)) | O36: =IF(N36="","",IF(MONTH(N36+1)<>MONTH(N36),"",N36+1)) | P36: =IF(O36="","",IF(MONTH(O36+1)<>MONTH(O36),"",O36+1)) | Q36: =IF(P36="","",IF(MONTH(P36+1)<>MONTH(P36),"",P36+1)) | R36: =IF(Q36="","",IF(MONTH(Q36+1)<>MONTH(Q36),"",Q36+1)) | S36: =IF(R36="","",IF(MONTH(R36+1)<>MONTH(R36),"",R36+1)) | AC36: =IF(AI35="","",IF(MONTH(AI35+1)<>MONTH(AI35),"",AI35+1)) | AD36: =IF(AC36="","",IF(MONTH(AC36+1)<>MONTH(AC36),"",AC36+1)) | AE36: =IF(AD36="","",IF(MONTH(AD36+1)<>MONTH(AD36),"",AD36+1)) | AF36: =IF(AE36="","",IF(MONTH(AE36+1)<>MONTH(AE36),"",AE36+1)) | AG36: =IF(AF36="","",IF(MONTH(AF36+1)<>MONTH(AF36),"",AF36+1)) | AH36: =IF(AG36="","",IF(MONTH(AG36+1)<>MONTH(AG36),"",AG36+1)) | AI36: =IF(AH36="","",IF(MONTH(AH36+1)<>MONTH(AH36),"",AH36+1))
